<?xml version="1.0"?>
<robot name="arm1">
  
  <!-- Link 1: Base Link -->
  <link name="base_link">
    <visual>
      <geometry>
        <mesh filename="package://arm1/urdf/arm1.stl"/> <!-- Update with correct STL path -->
      </geometry>
    </visual>
    <collision>
      <geometry>
        <mesh filename="package://arm1/urdf/base.stl"/> <!-- Collision geometry for base -->
      </geometry>
    </collision>
    <inertial>
      <mass value="1.0"/> <!-- Replace with actual mass -->
      <inertia  ixx="0.01" ixy="0.0" ixz="0.0" iyy="0.01" iyz="0.0" izz="0.01"/> <!-- Replace with actual inertia -->
    </inertial>
  </link>

  <!-- Joint 1: Connecting base to arm -->
  <joint name="base_to_arm" type="revolute">
    <parent link="base_link"/>
    <child link="arm_link"/>
    <origin xyz="0 0 1.0" rpy="0 0 0"/> <!-- Joint position and orientation -->
    <axis xyz="0 1 0"/> <!-- Axis of rotation for revolute joint -->
    <limit lower="0.0" upper="1.57" effort="100" velocity="1.0"/> <!-- Joint limits (modify as needed) -->
  </joint>

  <!-- Link 2: Arm Link -->
  <link name="arm_link">
    <visual>
      <geometry>
        <mesh filename="package://arm1/urdf/arm.stl"/> <!-- Update with correct STL path -->
      </geometry>
    </visual>
    <collision>
      <geometry>
        <mesh filename="package://arm1/urdf/arm.stl"/> <!-- Collision geometry for arm -->
      </geometry>
    </collision>
    <inertial>
      <mass value="2.0"/> <!-- Replace with actual mass -->
      <inertia  ixx="0.02" ixy="0.0" ixz="0.0" iyy="0.02" iyz="0.0" izz="0.02"/> <!-- Replace with actual inertia -->
    </inertial>
  </link>

</robot>
