<?xml version="1.0"?>
<robot name="arm1" xmlns:xacro="http://www.ros.org/wiki/xacro">

  <!-- Base Link -->
  <link name="base_link">
    <visual>
      <geometry>
        <box size="0.2 0.2 0.1"/>
      </geometry>
    </visual>
    <collision>
      <geometry>
        <box size="0.2 0.2 0.1"/>
      </geometry>
    </collision>
  </link>

  <!-- Arm Link -->
  <link name="arm_link">
    <visual>
      <geometry>
        <box size="0.1 0.1 0.5"/>
      </geometry>
    </visual>
    <collision>
      <geometry>
        <box size="0.1 0.1 0.5"/>
      </geometry>
    </collision>
  </link>

  <!-- Joint between base and arm -->
  <joint name="base_to_arm" type="revolute">
    <parent link="base_link"/>
    <child link="arm_link"/>
    <origin rpy="0 0 0" xyz="0 0 0.25"/>
    <axis xyz="0 0 1"/>
    <limit effort="10" velocity="1.0" lower="0" upper="1.57"/>
  </joint>

</robot>